<?xml version='1.0'?>
<robot xmlns:xacro="http://www.ros.org/wiki/xacro">
    <xacro:macro name="wheel" params="side x y z rx ry rz ax ay az color parent">
        <link name='wheel_${side}'>
            <visual name='wheel_${side}_visual'>
                <origin xyz="0.0 0.0 0.0" rpy="0.0 ${pi/2} ${pi/2}"/>
                <geometry>
                    <cylinder length="0.01" radius="0.05"/>
                </geometry>
                <material name="${color}"/>
            </visual>

            <collision name ='wheel_collision'>
                <origin xyz="0.0 0.0 0.0" rpy="0.0 ${pi/2} ${pi/2}"/>
                <geometry>
                    <cylinder length="0.01" radius="0.05"/>
                </geometry>
            </collision>

            <!-- plastic -->
            <xacro:inertial_cylinder mass="0.035" length="0.01" radius="0.05">
                <origin xyz="0.0 0.0 0.0" rpy="0.0 ${pi/2} ${pi/2}"/>
            </xacro:inertial_cylinder>
        </link>

        <joint name="wheel_${side}_joint" type="continuous">
            <origin xyz="${x} ${y} ${z}" rpy="${rx} ${ry} ${rz}"/>
            <axis xyz="${ax} ${ay} ${az}"/>

            <limit effort="100" velocity="50"/>
            <joint_properties damping="0.0" friction="0.0"/>

            <child link="wheel_${side}"/>
            <parent link="${parent}"/>
        </joint>
    </xacro:macro>
</robot>